2023-04-28 01:19:58,387 [ERROR   ] Traceback (most recent call last):
  File "C:\Users\pnknv\Documents\GitHub\yadisk_loader\dev_check_jupyter\test_logging.py", line 37, in log_test_other
    return 2 / val
ZeroDivisionError: division by zero

